2025-03-20 17:41:46,100 INFO    MainThread:307683 [wandb_setup.py:_flush():67] Current SDK version is 0.19.8
2025-03-20 17:41:46,100 INFO    MainThread:307683 [wandb_setup.py:_flush():67] Configure stats pid to 307683
2025-03-20 17:41:46,100 INFO    MainThread:307683 [wandb_setup.py:_flush():67] Loading settings from /home/inside-tech/.config/wandb/settings
2025-03-20 17:41:46,100 INFO    MainThread:307683 [wandb_setup.py:_flush():67] Loading settings from /home/inside-tech/Desktop/image_segmentation/wandb/settings
2025-03-20 17:41:46,100 INFO    MainThread:307683 [wandb_setup.py:_flush():67] Loading settings from environment variables
2025-03-20 17:41:46,100 INFO    MainThread:307683 [wandb_init.py:setup_run_log_directory():647] Logging user logs to /home/inside-tech/Desktop/image_segmentation/wandb/run-20250320_174146-uh9bn2pn/logs/debug.log
2025-03-20 17:41:46,100 INFO    MainThread:307683 [wandb_init.py:setup_run_log_directory():648] Logging internal logs to /home/inside-tech/Desktop/image_segmentation/wandb/run-20250320_174146-uh9bn2pn/logs/debug-internal.log
2025-03-20 17:41:46,100 INFO    MainThread:307683 [wandb_init.py:monkeypatch_ipython():599] configuring jupyter hooks <wandb.sdk.wandb_init._WandbInit object at 0x7495c3ff2720>
2025-03-20 17:41:46,100 INFO    MainThread:307683 [wandb_init.py:init():761] calling init triggers
2025-03-20 17:41:46,100 INFO    MainThread:307683 [wandb_init.py:init():766] wandb.init called with sweep_config: {}
config: {'_wandb': {}}
2025-03-20 17:41:46,100 INFO    MainThread:307683 [wandb_init.py:init():784] starting backend
2025-03-20 17:41:46,100 INFO    MainThread:307683 [wandb_init.py:init():788] sending inform_init request
2025-03-20 17:41:46,101 INFO    MainThread:307683 [backend.py:_multiprocessing_setup():101] multiprocessing start_methods=fork,spawn,forkserver, using: spawn
2025-03-20 17:41:46,101 INFO    MainThread:307683 [wandb_init.py:init():798] backend started and connected
2025-03-20 17:41:46,102 INFO    MainThread:307683 [wandb_run.py:_label_probe_notebook():1204] probe notebook
2025-03-20 17:41:46,102 INFO    MainThread:307683 [wandb_init.py:init():891] updated telemetry
2025-03-20 17:41:46,103 INFO    MainThread:307683 [wandb_init.py:init():915] communicating run to backend with 90.0 second timeout
2025-03-20 17:41:46,478 INFO    MainThread:307683 [wandb_init.py:init():990] starting run threads in backend
2025-03-20 17:41:46,539 INFO    MainThread:307683 [wandb_run.py:_console_start():2375] atexit reg
2025-03-20 17:41:46,540 INFO    MainThread:307683 [wandb_run.py:_redirect():2227] redirect: wrap_raw
2025-03-20 17:41:46,540 INFO    MainThread:307683 [wandb_run.py:_redirect():2292] Wrapping output streams.
2025-03-20 17:41:46,540 INFO    MainThread:307683 [wandb_run.py:_redirect():2315] Redirects installed.
2025-03-20 17:41:46,541 INFO    MainThread:307683 [wandb_init.py:init():1032] run started, returning control to user process
2025-03-20 17:42:56,957 INFO    MainThread:307683 [jupyter.py:save_ipynb():386] not saving jupyter notebook
2025-03-20 17:42:56,957 INFO    MainThread:307683 [wandb_init.py:_pause_backend():564] pausing backend
2025-03-20 17:42:56,960 INFO    MainThread:307683 [wandb_init.py:_resume_backend():569] resuming backend
2025-03-20 17:42:56,966 INFO    MainThread:307683 [jupyter.py:save_ipynb():386] not saving jupyter notebook
2025-03-20 17:42:56,966 INFO    MainThread:307683 [wandb_init.py:_pause_backend():564] pausing backend
2025-03-20 17:42:56,969 INFO    MainThread:307683 [wandb_init.py:_resume_backend():569] resuming backend
2025-03-20 17:42:56,975 INFO    MainThread:307683 [jupyter.py:save_ipynb():386] not saving jupyter notebook
2025-03-20 17:42:56,975 INFO    MainThread:307683 [wandb_init.py:_pause_backend():564] pausing backend
2025-03-20 17:42:56,978 INFO    MainThread:307683 [wandb_init.py:_resume_backend():569] resuming backend
2025-03-20 17:42:58,140 INFO    MainThread:307683 [jupyter.py:save_ipynb():386] not saving jupyter notebook
2025-03-20 17:42:58,140 INFO    MainThread:307683 [wandb_init.py:_pause_backend():564] pausing backend
2025-03-20 17:42:58,143 INFO    MainThread:307683 [wandb_init.py:_resume_backend():569] resuming backend
2025-03-20 17:42:58,144 INFO    MainThread:307683 [jupyter.py:save_ipynb():386] not saving jupyter notebook
2025-03-20 17:42:58,144 INFO    MainThread:307683 [wandb_init.py:_pause_backend():564] pausing backend
2025-03-20 17:42:58,148 INFO    MainThread:307683 [wandb_init.py:_resume_backend():569] resuming backend
2025-03-20 17:42:59,296 INFO    MainThread:307683 [jupyter.py:save_ipynb():386] not saving jupyter notebook
2025-03-20 17:42:59,296 INFO    MainThread:307683 [wandb_init.py:_pause_backend():564] pausing backend
2025-03-20 17:43:20,969 INFO    MainThread:307683 [wandb_init.py:_resume_backend():569] resuming backend
2025-03-20 17:43:20,971 INFO    MainThread:307683 [jupyter.py:save_ipynb():386] not saving jupyter notebook
2025-03-20 17:43:20,971 INFO    MainThread:307683 [wandb_init.py:_pause_backend():564] pausing backend
2025-03-20 17:43:23,866 INFO    MainThread:307683 [wandb_init.py:_resume_backend():569] resuming backend
2025-03-20 17:43:23,867 INFO    MainThread:307683 [jupyter.py:save_ipynb():386] not saving jupyter notebook
2025-03-20 17:43:23,867 INFO    MainThread:307683 [wandb_init.py:_pause_backend():564] pausing backend
2025-03-20 17:43:27,441 INFO    MainThread:307683 [wandb_init.py:_resume_backend():569] resuming backend
2025-03-20 17:43:27,442 INFO    MainThread:307683 [jupyter.py:save_ipynb():386] not saving jupyter notebook
2025-03-20 17:43:27,442 INFO    MainThread:307683 [wandb_init.py:_pause_backend():564] pausing backend
2025-03-20 17:43:41,643 INFO    MainThread:307683 [wandb_init.py:_resume_backend():569] resuming backend
2025-03-20 17:43:41,646 INFO    MainThread:307683 [jupyter.py:save_ipynb():386] not saving jupyter notebook
2025-03-20 17:43:41,646 INFO    MainThread:307683 [wandb_init.py:_pause_backend():564] pausing backend
2025-03-20 17:43:41,905 INFO    MainThread:307683 [wandb_init.py:_resume_backend():569] resuming backend
2025-03-20 17:43:41,907 INFO    MainThread:307683 [jupyter.py:save_ipynb():386] not saving jupyter notebook
2025-03-20 17:43:41,911 INFO    MainThread:307683 [wandb_init.py:_pause_backend():564] pausing backend
2025-03-20 17:43:42,106 INFO    MainThread:307683 [wandb_init.py:_resume_backend():569] resuming backend
2025-03-20 17:43:42,112 INFO    MainThread:307683 [jupyter.py:save_ipynb():386] not saving jupyter notebook
2025-03-20 17:43:42,112 INFO    MainThread:307683 [wandb_init.py:_pause_backend():564] pausing backend
2025-03-20 17:43:45,024 INFO    MainThread:307683 [wandb_init.py:_resume_backend():569] resuming backend
2025-03-20 17:43:45,025 INFO    MainThread:307683 [jupyter.py:save_ipynb():386] not saving jupyter notebook
2025-03-20 17:43:45,025 INFO    MainThread:307683 [wandb_init.py:_pause_backend():564] pausing backend
2025-03-20 17:43:54,273 INFO    MainThread:307683 [wandb_init.py:_resume_backend():569] resuming backend
2025-03-20 17:43:54,277 INFO    MainThread:307683 [jupyter.py:save_ipynb():386] not saving jupyter notebook
2025-03-20 17:43:54,280 INFO    MainThread:307683 [wandb_init.py:_pause_backend():564] pausing backend
2025-03-20 17:43:54,421 INFO    MainThread:307683 [wandb_init.py:_resume_backend():569] resuming backend
2025-03-20 17:43:54,423 INFO    MainThread:307683 [jupyter.py:save_ipynb():386] not saving jupyter notebook
2025-03-20 17:43:54,428 INFO    MainThread:307683 [wandb_init.py:_pause_backend():564] pausing backend
2025-03-20 17:43:54,604 INFO    MainThread:307683 [wandb_init.py:_resume_backend():569] resuming backend
2025-03-20 17:43:54,605 INFO    MainThread:307683 [jupyter.py:save_ipynb():386] not saving jupyter notebook
2025-03-20 17:43:54,610 INFO    MainThread:307683 [wandb_init.py:_pause_backend():564] pausing backend
2025-03-20 17:43:55,805 INFO    MainThread:307683 [wandb_init.py:_resume_backend():569] resuming backend
2025-03-20 17:43:55,811 INFO    MainThread:307683 [jupyter.py:save_ipynb():386] not saving jupyter notebook
2025-03-20 17:43:55,811 INFO    MainThread:307683 [wandb_init.py:_pause_backend():564] pausing backend
2025-03-20 17:43:55,916 INFO    MainThread:307683 [wandb_init.py:_resume_backend():569] resuming backend
2025-03-20 17:43:55,918 INFO    MainThread:307683 [jupyter.py:save_ipynb():386] not saving jupyter notebook
2025-03-20 17:43:55,922 INFO    MainThread:307683 [wandb_init.py:_pause_backend():564] pausing backend
2025-03-20 17:44:03,925 INFO    MainThread:307683 [wandb_init.py:_resume_backend():569] resuming backend
2025-03-20 17:47:33,764 WARNING MsgRouterThr:307683 [router.py:message_loop():63] message_loop has been closed
Traceback (most recent call last):
  File "/home/inside-tech/Desktop/image_segmentation/.venv/lib/python3.12/site-packages/wandb/sdk/interface/router_sock.py", line 27, in _read_message
    return self._sock_client.read_server_response(timeout=1)
           ^^^^^^^^^^^^^^^^^^^^^^^^^^^^^^^^^^^^^^^^^^^^^^^^^
  File "/home/inside-tech/Desktop/image_segmentation/.venv/lib/python3.12/site-packages/wandb/sdk/lib/sock_client.py", line 235, in read_server_response
    data = self._read_packet_bytes(timeout=timeout)
           ^^^^^^^^^^^^^^^^^^^^^^^^^^^^^^^^^^^^^^^^
  File "/home/inside-tech/Desktop/image_segmentation/.venv/lib/python3.12/site-packages/wandb/sdk/lib/sock_client.py", line 220, in _read_packet_bytes
    raise SockClientClosedError
wandb.sdk.lib.sock_client.SockClientClosedError

The above exception was the direct cause of the following exception:

Traceback (most recent call last):
  File "/home/inside-tech/Desktop/image_segmentation/.venv/lib/python3.12/site-packages/wandb/sdk/interface/router.py", line 56, in message_loop
    msg = self._read_message()
          ^^^^^^^^^^^^^^^^^^^^
  File "/home/inside-tech/Desktop/image_segmentation/.venv/lib/python3.12/site-packages/wandb/sdk/interface/router_sock.py", line 29, in _read_message
    raise MessageRouterClosedError from e
wandb.sdk.interface.router.MessageRouterClosedError
2025-03-20 17:47:33,765 INFO    MsgRouterThr:307683 [mailbox.py:close():129] Closing mailbox, abandoning 1 handles.
2025-03-20 17:47:35,412 INFO    MainThread:307683 [jupyter.py:save_ipynb():386] not saving jupyter notebook
2025-03-20 17:47:35,412 INFO    MainThread:307683 [wandb_init.py:_pause_backend():564] pausing backend
2025-03-20 17:47:49,836 INFO    MainThread:307683 [wandb_init.py:_resume_backend():569] resuming backend
2025-03-20 17:47:49,837 ERROR   MainThread:307683 [redirect.py:_on_write():661] error in stdout callback
Traceback (most recent call last):
  File "/home/inside-tech/Desktop/image_segmentation/.venv/lib/python3.12/site-packages/IPython/core/events.py", line 82, in trigger
    func(*args, **kwargs)
  File "/home/inside-tech/Desktop/image_segmentation/.venv/lib/python3.12/site-packages/wandb/sdk/wandb_init.py", line 570, in _resume_backend
    self.backend.interface.publish_resume()
  File "/home/inside-tech/Desktop/image_segmentation/.venv/lib/python3.12/site-packages/wandb/sdk/interface/interface.py", line 777, in publish_resume
    self._publish_resume(resume)
  File "/home/inside-tech/Desktop/image_segmentation/.venv/lib/python3.12/site-packages/wandb/sdk/interface/interface_shared.py", line 293, in _publish_resume
    self._publish(rec)
  File "/home/inside-tech/Desktop/image_segmentation/.venv/lib/python3.12/site-packages/wandb/sdk/interface/interface_sock.py", line 39, in _publish
    self._sock_client.send_record_publish(record)
  File "/home/inside-tech/Desktop/image_segmentation/.venv/lib/python3.12/site-packages/wandb/sdk/lib/sock_client.py", line 174, in send_record_publish
    self.send_server_request(server_req)
  File "/home/inside-tech/Desktop/image_segmentation/.venv/lib/python3.12/site-packages/wandb/sdk/lib/sock_client.py", line 154, in send_server_request
    self._send_message(msg)
  File "/home/inside-tech/Desktop/image_segmentation/.venv/lib/python3.12/site-packages/wandb/sdk/lib/sock_client.py", line 151, in _send_message
    self._sendall_with_error_handle(header + data)
  File "/home/inside-tech/Desktop/image_segmentation/.venv/lib/python3.12/site-packages/wandb/sdk/lib/sock_client.py", line 130, in _sendall_with_error_handle
    sent = self._sock.send(data)
           ^^^^^^^^^^^^^^^^^^^^^
BrokenPipeError: [Errno 32] Broken pipe

During handling of the above exception, another exception occurred:

Traceback (most recent call last):
  File "/home/inside-tech/Desktop/image_segmentation/.venv/lib/python3.12/site-packages/wandb/sdk/lib/redirect.py", line 659, in _on_write
    cb(written_data)
  File "/home/inside-tech/Desktop/image_segmentation/.venv/lib/python3.12/site-packages/wandb/sdk/wandb_run.py", line 2296, in <lambda>
    lambda data: self._console_raw_callback("stdout", data),
                 ^^^^^^^^^^^^^^^^^^^^^^^^^^^^^^^^^^^^^^^^^^
  File "/home/inside-tech/Desktop/image_segmentation/.venv/lib/python3.12/site-packages/wandb/sdk/wandb_run.py", line 401, in wrapper_fn
    return func(self, *args, **kwargs)
           ^^^^^^^^^^^^^^^^^^^^^^^^^^^
  File "/home/inside-tech/Desktop/image_segmentation/.venv/lib/python3.12/site-packages/wandb/sdk/wandb_run.py", line 1444, in _console_raw_callback
    self._backend.interface.publish_output_raw(name, data)
  File "/home/inside-tech/Desktop/image_segmentation/.venv/lib/python3.12/site-packages/wandb/sdk/interface/interface.py", line 761, in publish_output_raw
    self._publish_output_raw(o)
  File "/home/inside-tech/Desktop/image_segmentation/.venv/lib/python3.12/site-packages/wandb/sdk/interface/interface_shared.py", line 38, in _publish_output_raw
    self._publish(rec)
  File "/home/inside-tech/Desktop/image_segmentation/.venv/lib/python3.12/site-packages/wandb/sdk/interface/interface_sock.py", line 39, in _publish
    self._sock_client.send_record_publish(record)
  File "/home/inside-tech/Desktop/image_segmentation/.venv/lib/python3.12/site-packages/wandb/sdk/lib/sock_client.py", line 174, in send_record_publish
    self.send_server_request(server_req)
  File "/home/inside-tech/Desktop/image_segmentation/.venv/lib/python3.12/site-packages/wandb/sdk/lib/sock_client.py", line 154, in send_server_request
    self._send_message(msg)
  File "/home/inside-tech/Desktop/image_segmentation/.venv/lib/python3.12/site-packages/wandb/sdk/lib/sock_client.py", line 151, in _send_message
    self._sendall_with_error_handle(header + data)
  File "/home/inside-tech/Desktop/image_segmentation/.venv/lib/python3.12/site-packages/wandb/sdk/lib/sock_client.py", line 130, in _sendall_with_error_handle
    sent = self._sock.send(data)
           ^^^^^^^^^^^^^^^^^^^^^
BrokenPipeError: [Errno 32] Broken pipe
2025-03-20 17:47:49,839 ERROR   MainThread:307683 [redirect.py:_on_write():661] error in stdout callback
Traceback (most recent call last):
  File "/home/inside-tech/Desktop/image_segmentation/.venv/lib/python3.12/site-packages/IPython/core/events.py", line 82, in trigger
    func(*args, **kwargs)
  File "/home/inside-tech/Desktop/image_segmentation/.venv/lib/python3.12/site-packages/wandb/sdk/wandb_init.py", line 570, in _resume_backend
    self.backend.interface.publish_resume()
  File "/home/inside-tech/Desktop/image_segmentation/.venv/lib/python3.12/site-packages/wandb/sdk/interface/interface.py", line 777, in publish_resume
    self._publish_resume(resume)
  File "/home/inside-tech/Desktop/image_segmentation/.venv/lib/python3.12/site-packages/wandb/sdk/interface/interface_shared.py", line 293, in _publish_resume
    self._publish(rec)
  File "/home/inside-tech/Desktop/image_segmentation/.venv/lib/python3.12/site-packages/wandb/sdk/interface/interface_sock.py", line 39, in _publish
    self._sock_client.send_record_publish(record)
  File "/home/inside-tech/Desktop/image_segmentation/.venv/lib/python3.12/site-packages/wandb/sdk/lib/sock_client.py", line 174, in send_record_publish
    self.send_server_request(server_req)
  File "/home/inside-tech/Desktop/image_segmentation/.venv/lib/python3.12/site-packages/wandb/sdk/lib/sock_client.py", line 154, in send_server_request
    self._send_message(msg)
  File "/home/inside-tech/Desktop/image_segmentation/.venv/lib/python3.12/site-packages/wandb/sdk/lib/sock_client.py", line 151, in _send_message
    self._sendall_with_error_handle(header + data)
  File "/home/inside-tech/Desktop/image_segmentation/.venv/lib/python3.12/site-packages/wandb/sdk/lib/sock_client.py", line 130, in _sendall_with_error_handle
    sent = self._sock.send(data)
           ^^^^^^^^^^^^^^^^^^^^^
BrokenPipeError: [Errno 32] Broken pipe

During handling of the above exception, another exception occurred:

Traceback (most recent call last):
  File "/home/inside-tech/Desktop/image_segmentation/.venv/lib/python3.12/site-packages/wandb/sdk/lib/redirect.py", line 659, in _on_write
    cb(written_data)
  File "/home/inside-tech/Desktop/image_segmentation/.venv/lib/python3.12/site-packages/wandb/sdk/wandb_run.py", line 2296, in <lambda>
    lambda data: self._console_raw_callback("stdout", data),
                 ^^^^^^^^^^^^^^^^^^^^^^^^^^^^^^^^^^^^^^^^^^
  File "/home/inside-tech/Desktop/image_segmentation/.venv/lib/python3.12/site-packages/wandb/sdk/wandb_run.py", line 401, in wrapper_fn
    return func(self, *args, **kwargs)
           ^^^^^^^^^^^^^^^^^^^^^^^^^^^
  File "/home/inside-tech/Desktop/image_segmentation/.venv/lib/python3.12/site-packages/wandb/sdk/wandb_run.py", line 1444, in _console_raw_callback
    self._backend.interface.publish_output_raw(name, data)
  File "/home/inside-tech/Desktop/image_segmentation/.venv/lib/python3.12/site-packages/wandb/sdk/interface/interface.py", line 761, in publish_output_raw
    self._publish_output_raw(o)
  File "/home/inside-tech/Desktop/image_segmentation/.venv/lib/python3.12/site-packages/wandb/sdk/interface/interface_shared.py", line 38, in _publish_output_raw
    self._publish(rec)
  File "/home/inside-tech/Desktop/image_segmentation/.venv/lib/python3.12/site-packages/wandb/sdk/interface/interface_sock.py", line 39, in _publish
    self._sock_client.send_record_publish(record)
  File "/home/inside-tech/Desktop/image_segmentation/.venv/lib/python3.12/site-packages/wandb/sdk/lib/sock_client.py", line 174, in send_record_publish
    self.send_server_request(server_req)
  File "/home/inside-tech/Desktop/image_segmentation/.venv/lib/python3.12/site-packages/wandb/sdk/lib/sock_client.py", line 154, in send_server_request
    self._send_message(msg)
  File "/home/inside-tech/Desktop/image_segmentation/.venv/lib/python3.12/site-packages/wandb/sdk/lib/sock_client.py", line 151, in _send_message
    self._sendall_with_error_handle(header + data)
  File "/home/inside-tech/Desktop/image_segmentation/.venv/lib/python3.12/site-packages/wandb/sdk/lib/sock_client.py", line 130, in _sendall_with_error_handle
    sent = self._sock.send(data)
           ^^^^^^^^^^^^^^^^^^^^^
BrokenPipeError: [Errno 32] Broken pipe
2025-03-20 17:47:49,953 ERROR   MainThread:307683 [redirect.py:_on_write():661] error in stdout callback
Traceback (most recent call last):
  File "/home/inside-tech/Desktop/image_segmentation/.venv/lib/python3.12/site-packages/wandb/sdk/lib/redirect.py", line 659, in _on_write
    cb(written_data)
  File "/home/inside-tech/Desktop/image_segmentation/.venv/lib/python3.12/site-packages/wandb/sdk/wandb_run.py", line 2296, in <lambda>
    lambda data: self._console_raw_callback("stdout", data),
                 ^^^^^^^^^^^^^^^^^^^^^^^^^^^^^^^^^^^^^^^^^^
  File "/home/inside-tech/Desktop/image_segmentation/.venv/lib/python3.12/site-packages/wandb/sdk/wandb_run.py", line 401, in wrapper_fn
    return func(self, *args, **kwargs)
           ^^^^^^^^^^^^^^^^^^^^^^^^^^^
  File "/home/inside-tech/Desktop/image_segmentation/.venv/lib/python3.12/site-packages/wandb/sdk/wandb_run.py", line 1444, in _console_raw_callback
    self._backend.interface.publish_output_raw(name, data)
  File "/home/inside-tech/Desktop/image_segmentation/.venv/lib/python3.12/site-packages/wandb/sdk/interface/interface.py", line 761, in publish_output_raw
    self._publish_output_raw(o)
  File "/home/inside-tech/Desktop/image_segmentation/.venv/lib/python3.12/site-packages/wandb/sdk/interface/interface_shared.py", line 38, in _publish_output_raw
    self._publish(rec)
  File "/home/inside-tech/Desktop/image_segmentation/.venv/lib/python3.12/site-packages/wandb/sdk/interface/interface_sock.py", line 39, in _publish
    self._sock_client.send_record_publish(record)
  File "/home/inside-tech/Desktop/image_segmentation/.venv/lib/python3.12/site-packages/wandb/sdk/lib/sock_client.py", line 174, in send_record_publish
    self.send_server_request(server_req)
  File "/home/inside-tech/Desktop/image_segmentation/.venv/lib/python3.12/site-packages/wandb/sdk/lib/sock_client.py", line 154, in send_server_request
    self._send_message(msg)
  File "/home/inside-tech/Desktop/image_segmentation/.venv/lib/python3.12/site-packages/wandb/sdk/lib/sock_client.py", line 151, in _send_message
    self._sendall_with_error_handle(header + data)
  File "/home/inside-tech/Desktop/image_segmentation/.venv/lib/python3.12/site-packages/wandb/sdk/lib/sock_client.py", line 130, in _sendall_with_error_handle
    sent = self._sock.send(data)
           ^^^^^^^^^^^^^^^^^^^^^
BrokenPipeError: [Errno 32] Broken pipe
2025-03-20 17:47:49,953 ERROR   MainThread:307683 [redirect.py:_on_write():661] error in stdout callback
Traceback (most recent call last):
  File "/home/inside-tech/Desktop/image_segmentation/.venv/lib/python3.12/site-packages/wandb/sdk/lib/redirect.py", line 659, in _on_write
    cb(written_data)
  File "/home/inside-tech/Desktop/image_segmentation/.venv/lib/python3.12/site-packages/wandb/sdk/wandb_run.py", line 2296, in <lambda>
    lambda data: self._console_raw_callback("stdout", data),
                 ^^^^^^^^^^^^^^^^^^^^^^^^^^^^^^^^^^^^^^^^^^
  File "/home/inside-tech/Desktop/image_segmentation/.venv/lib/python3.12/site-packages/wandb/sdk/wandb_run.py", line 401, in wrapper_fn
    return func(self, *args, **kwargs)
           ^^^^^^^^^^^^^^^^^^^^^^^^^^^
  File "/home/inside-tech/Desktop/image_segmentation/.venv/lib/python3.12/site-packages/wandb/sdk/wandb_run.py", line 1444, in _console_raw_callback
    self._backend.interface.publish_output_raw(name, data)
  File "/home/inside-tech/Desktop/image_segmentation/.venv/lib/python3.12/site-packages/wandb/sdk/interface/interface.py", line 761, in publish_output_raw
    self._publish_output_raw(o)
  File "/home/inside-tech/Desktop/image_segmentation/.venv/lib/python3.12/site-packages/wandb/sdk/interface/interface_shared.py", line 38, in _publish_output_raw
    self._publish(rec)
  File "/home/inside-tech/Desktop/image_segmentation/.venv/lib/python3.12/site-packages/wandb/sdk/interface/interface_sock.py", line 39, in _publish
    self._sock_client.send_record_publish(record)
  File "/home/inside-tech/Desktop/image_segmentation/.venv/lib/python3.12/site-packages/wandb/sdk/lib/sock_client.py", line 174, in send_record_publish
    self.send_server_request(server_req)
  File "/home/inside-tech/Desktop/image_segmentation/.venv/lib/python3.12/site-packages/wandb/sdk/lib/sock_client.py", line 154, in send_server_request
    self._send_message(msg)
  File "/home/inside-tech/Desktop/image_segmentation/.venv/lib/python3.12/site-packages/wandb/sdk/lib/sock_client.py", line 151, in _send_message
    self._sendall_with_error_handle(header + data)
  File "/home/inside-tech/Desktop/image_segmentation/.venv/lib/python3.12/site-packages/wandb/sdk/lib/sock_client.py", line 130, in _sendall_with_error_handle
    sent = self._sock.send(data)
           ^^^^^^^^^^^^^^^^^^^^^
BrokenPipeError: [Errno 32] Broken pipe
2025-03-20 17:47:50,935 INFO    MainThread:307683 [jupyter.py:save_ipynb():386] not saving jupyter notebook
2025-03-20 17:47:50,935 INFO    MainThread:307683 [wandb_init.py:_pause_backend():564] pausing backend
2025-03-20 17:47:50,935 ERROR   MainThread:307683 [redirect.py:_on_write():661] error in stdout callback
Traceback (most recent call last):
  File "/home/inside-tech/Desktop/image_segmentation/.venv/lib/python3.12/site-packages/IPython/core/events.py", line 82, in trigger
    func(*args, **kwargs)
  File "/home/inside-tech/Desktop/image_segmentation/.venv/lib/python3.12/site-packages/wandb/sdk/wandb_init.py", line 565, in _pause_backend
    self.backend.interface.publish_pause()
  File "/home/inside-tech/Desktop/image_segmentation/.venv/lib/python3.12/site-packages/wandb/sdk/interface/interface.py", line 769, in publish_pause
    self._publish_pause(pause)
  File "/home/inside-tech/Desktop/image_segmentation/.venv/lib/python3.12/site-packages/wandb/sdk/interface/interface_shared.py", line 289, in _publish_pause
    self._publish(rec)
  File "/home/inside-tech/Desktop/image_segmentation/.venv/lib/python3.12/site-packages/wandb/sdk/interface/interface_sock.py", line 39, in _publish
    self._sock_client.send_record_publish(record)
  File "/home/inside-tech/Desktop/image_segmentation/.venv/lib/python3.12/site-packages/wandb/sdk/lib/sock_client.py", line 174, in send_record_publish
    self.send_server_request(server_req)
  File "/home/inside-tech/Desktop/image_segmentation/.venv/lib/python3.12/site-packages/wandb/sdk/lib/sock_client.py", line 154, in send_server_request
    self._send_message(msg)
  File "/home/inside-tech/Desktop/image_segmentation/.venv/lib/python3.12/site-packages/wandb/sdk/lib/sock_client.py", line 151, in _send_message
    self._sendall_with_error_handle(header + data)
  File "/home/inside-tech/Desktop/image_segmentation/.venv/lib/python3.12/site-packages/wandb/sdk/lib/sock_client.py", line 130, in _sendall_with_error_handle
    sent = self._sock.send(data)
           ^^^^^^^^^^^^^^^^^^^^^
BrokenPipeError: [Errno 32] Broken pipe

During handling of the above exception, another exception occurred:

Traceback (most recent call last):
  File "/home/inside-tech/Desktop/image_segmentation/.venv/lib/python3.12/site-packages/wandb/sdk/lib/redirect.py", line 659, in _on_write
    cb(written_data)
  File "/home/inside-tech/Desktop/image_segmentation/.venv/lib/python3.12/site-packages/wandb/sdk/wandb_run.py", line 2296, in <lambda>
    lambda data: self._console_raw_callback("stdout", data),
                 ^^^^^^^^^^^^^^^^^^^^^^^^^^^^^^^^^^^^^^^^^^
  File "/home/inside-tech/Desktop/image_segmentation/.venv/lib/python3.12/site-packages/wandb/sdk/wandb_run.py", line 401, in wrapper_fn
    return func(self, *args, **kwargs)
           ^^^^^^^^^^^^^^^^^^^^^^^^^^^
  File "/home/inside-tech/Desktop/image_segmentation/.venv/lib/python3.12/site-packages/wandb/sdk/wandb_run.py", line 1444, in _console_raw_callback
    self._backend.interface.publish_output_raw(name, data)
  File "/home/inside-tech/Desktop/image_segmentation/.venv/lib/python3.12/site-packages/wandb/sdk/interface/interface.py", line 761, in publish_output_raw
    self._publish_output_raw(o)
  File "/home/inside-tech/Desktop/image_segmentation/.venv/lib/python3.12/site-packages/wandb/sdk/interface/interface_shared.py", line 38, in _publish_output_raw
    self._publish(rec)
  File "/home/inside-tech/Desktop/image_segmentation/.venv/lib/python3.12/site-packages/wandb/sdk/interface/interface_sock.py", line 39, in _publish
    self._sock_client.send_record_publish(record)
  File "/home/inside-tech/Desktop/image_segmentation/.venv/lib/python3.12/site-packages/wandb/sdk/lib/sock_client.py", line 174, in send_record_publish
    self.send_server_request(server_req)
  File "/home/inside-tech/Desktop/image_segmentation/.venv/lib/python3.12/site-packages/wandb/sdk/lib/sock_client.py", line 154, in send_server_request
    self._send_message(msg)
  File "/home/inside-tech/Desktop/image_segmentation/.venv/lib/python3.12/site-packages/wandb/sdk/lib/sock_client.py", line 151, in _send_message
    self._sendall_with_error_handle(header + data)
  File "/home/inside-tech/Desktop/image_segmentation/.venv/lib/python3.12/site-packages/wandb/sdk/lib/sock_client.py", line 130, in _sendall_with_error_handle
    sent = self._sock.send(data)
           ^^^^^^^^^^^^^^^^^^^^^
BrokenPipeError: [Errno 32] Broken pipe
2025-03-20 17:47:50,936 ERROR   MainThread:307683 [redirect.py:_on_write():661] error in stdout callback
Traceback (most recent call last):
  File "/home/inside-tech/Desktop/image_segmentation/.venv/lib/python3.12/site-packages/IPython/core/events.py", line 82, in trigger
    func(*args, **kwargs)
  File "/home/inside-tech/Desktop/image_segmentation/.venv/lib/python3.12/site-packages/wandb/sdk/wandb_init.py", line 565, in _pause_backend
    self.backend.interface.publish_pause()
  File "/home/inside-tech/Desktop/image_segmentation/.venv/lib/python3.12/site-packages/wandb/sdk/interface/interface.py", line 769, in publish_pause
    self._publish_pause(pause)
  File "/home/inside-tech/Desktop/image_segmentation/.venv/lib/python3.12/site-packages/wandb/sdk/interface/interface_shared.py", line 289, in _publish_pause
    self._publish(rec)
  File "/home/inside-tech/Desktop/image_segmentation/.venv/lib/python3.12/site-packages/wandb/sdk/interface/interface_sock.py", line 39, in _publish
    self._sock_client.send_record_publish(record)
  File "/home/inside-tech/Desktop/image_segmentation/.venv/lib/python3.12/site-packages/wandb/sdk/lib/sock_client.py", line 174, in send_record_publish
    self.send_server_request(server_req)
  File "/home/inside-tech/Desktop/image_segmentation/.venv/lib/python3.12/site-packages/wandb/sdk/lib/sock_client.py", line 154, in send_server_request
    self._send_message(msg)
  File "/home/inside-tech/Desktop/image_segmentation/.venv/lib/python3.12/site-packages/wandb/sdk/lib/sock_client.py", line 151, in _send_message
    self._sendall_with_error_handle(header + data)
  File "/home/inside-tech/Desktop/image_segmentation/.venv/lib/python3.12/site-packages/wandb/sdk/lib/sock_client.py", line 130, in _sendall_with_error_handle
    sent = self._sock.send(data)
           ^^^^^^^^^^^^^^^^^^^^^
BrokenPipeError: [Errno 32] Broken pipe

During handling of the above exception, another exception occurred:

Traceback (most recent call last):
  File "/home/inside-tech/Desktop/image_segmentation/.venv/lib/python3.12/site-packages/wandb/sdk/lib/redirect.py", line 659, in _on_write
    cb(written_data)
  File "/home/inside-tech/Desktop/image_segmentation/.venv/lib/python3.12/site-packages/wandb/sdk/wandb_run.py", line 2296, in <lambda>
    lambda data: self._console_raw_callback("stdout", data),
                 ^^^^^^^^^^^^^^^^^^^^^^^^^^^^^^^^^^^^^^^^^^
  File "/home/inside-tech/Desktop/image_segmentation/.venv/lib/python3.12/site-packages/wandb/sdk/wandb_run.py", line 401, in wrapper_fn
    return func(self, *args, **kwargs)
           ^^^^^^^^^^^^^^^^^^^^^^^^^^^
  File "/home/inside-tech/Desktop/image_segmentation/.venv/lib/python3.12/site-packages/wandb/sdk/wandb_run.py", line 1444, in _console_raw_callback
    self._backend.interface.publish_output_raw(name, data)
  File "/home/inside-tech/Desktop/image_segmentation/.venv/lib/python3.12/site-packages/wandb/sdk/interface/interface.py", line 761, in publish_output_raw
    self._publish_output_raw(o)
  File "/home/inside-tech/Desktop/image_segmentation/.venv/lib/python3.12/site-packages/wandb/sdk/interface/interface_shared.py", line 38, in _publish_output_raw
    self._publish(rec)
  File "/home/inside-tech/Desktop/image_segmentation/.venv/lib/python3.12/site-packages/wandb/sdk/interface/interface_sock.py", line 39, in _publish
    self._sock_client.send_record_publish(record)
  File "/home/inside-tech/Desktop/image_segmentation/.venv/lib/python3.12/site-packages/wandb/sdk/lib/sock_client.py", line 174, in send_record_publish
    self.send_server_request(server_req)
  File "/home/inside-tech/Desktop/image_segmentation/.venv/lib/python3.12/site-packages/wandb/sdk/lib/sock_client.py", line 154, in send_server_request
    self._send_message(msg)
  File "/home/inside-tech/Desktop/image_segmentation/.venv/lib/python3.12/site-packages/wandb/sdk/lib/sock_client.py", line 151, in _send_message
    self._sendall_with_error_handle(header + data)
  File "/home/inside-tech/Desktop/image_segmentation/.venv/lib/python3.12/site-packages/wandb/sdk/lib/sock_client.py", line 130, in _sendall_with_error_handle
    sent = self._sock.send(data)
           ^^^^^^^^^^^^^^^^^^^^^
BrokenPipeError: [Errno 32] Broken pipe
2025-03-20 17:47:57,242 INFO    MainThread:307683 [wandb_init.py:_resume_backend():569] resuming backend
2025-03-20 17:47:57,242 ERROR   MainThread:307683 [redirect.py:_on_write():661] error in stdout callback
Traceback (most recent call last):
  File "/home/inside-tech/Desktop/image_segmentation/.venv/lib/python3.12/site-packages/IPython/core/events.py", line 82, in trigger
    func(*args, **kwargs)
  File "/home/inside-tech/Desktop/image_segmentation/.venv/lib/python3.12/site-packages/wandb/sdk/wandb_init.py", line 570, in _resume_backend
    self.backend.interface.publish_resume()
  File "/home/inside-tech/Desktop/image_segmentation/.venv/lib/python3.12/site-packages/wandb/sdk/interface/interface.py", line 777, in publish_resume
    self._publish_resume(resume)
  File "/home/inside-tech/Desktop/image_segmentation/.venv/lib/python3.12/site-packages/wandb/sdk/interface/interface_shared.py", line 293, in _publish_resume
    self._publish(rec)
  File "/home/inside-tech/Desktop/image_segmentation/.venv/lib/python3.12/site-packages/wandb/sdk/interface/interface_sock.py", line 39, in _publish
    self._sock_client.send_record_publish(record)
  File "/home/inside-tech/Desktop/image_segmentation/.venv/lib/python3.12/site-packages/wandb/sdk/lib/sock_client.py", line 174, in send_record_publish
    self.send_server_request(server_req)
  File "/home/inside-tech/Desktop/image_segmentation/.venv/lib/python3.12/site-packages/wandb/sdk/lib/sock_client.py", line 154, in send_server_request
    self._send_message(msg)
  File "/home/inside-tech/Desktop/image_segmentation/.venv/lib/python3.12/site-packages/wandb/sdk/lib/sock_client.py", line 151, in _send_message
    self._sendall_with_error_handle(header + data)
  File "/home/inside-tech/Desktop/image_segmentation/.venv/lib/python3.12/site-packages/wandb/sdk/lib/sock_client.py", line 130, in _sendall_with_error_handle
    sent = self._sock.send(data)
           ^^^^^^^^^^^^^^^^^^^^^
BrokenPipeError: [Errno 32] Broken pipe

During handling of the above exception, another exception occurred:

Traceback (most recent call last):
  File "/home/inside-tech/Desktop/image_segmentation/.venv/lib/python3.12/site-packages/wandb/sdk/lib/redirect.py", line 659, in _on_write
    cb(written_data)
  File "/home/inside-tech/Desktop/image_segmentation/.venv/lib/python3.12/site-packages/wandb/sdk/wandb_run.py", line 2296, in <lambda>
    lambda data: self._console_raw_callback("stdout", data),
                 ^^^^^^^^^^^^^^^^^^^^^^^^^^^^^^^^^^^^^^^^^^
  File "/home/inside-tech/Desktop/image_segmentation/.venv/lib/python3.12/site-packages/wandb/sdk/wandb_run.py", line 401, in wrapper_fn
    return func(self, *args, **kwargs)
           ^^^^^^^^^^^^^^^^^^^^^^^^^^^
  File "/home/inside-tech/Desktop/image_segmentation/.venv/lib/python3.12/site-packages/wandb/sdk/wandb_run.py", line 1444, in _console_raw_callback
    self._backend.interface.publish_output_raw(name, data)
  File "/home/inside-tech/Desktop/image_segmentation/.venv/lib/python3.12/site-packages/wandb/sdk/interface/interface.py", line 761, in publish_output_raw
    self._publish_output_raw(o)
  File "/home/inside-tech/Desktop/image_segmentation/.venv/lib/python3.12/site-packages/wandb/sdk/interface/interface_shared.py", line 38, in _publish_output_raw
    self._publish(rec)
  File "/home/inside-tech/Desktop/image_segmentation/.venv/lib/python3.12/site-packages/wandb/sdk/interface/interface_sock.py", line 39, in _publish
    self._sock_client.send_record_publish(record)
  File "/home/inside-tech/Desktop/image_segmentation/.venv/lib/python3.12/site-packages/wandb/sdk/lib/sock_client.py", line 174, in send_record_publish
    self.send_server_request(server_req)
  File "/home/inside-tech/Desktop/image_segmentation/.venv/lib/python3.12/site-packages/wandb/sdk/lib/sock_client.py", line 154, in send_server_request
    self._send_message(msg)
  File "/home/inside-tech/Desktop/image_segmentation/.venv/lib/python3.12/site-packages/wandb/sdk/lib/sock_client.py", line 151, in _send_message
    self._sendall_with_error_handle(header + data)
  File "/home/inside-tech/Desktop/image_segmentation/.venv/lib/python3.12/site-packages/wandb/sdk/lib/sock_client.py", line 130, in _sendall_with_error_handle
    sent = self._sock.send(data)
           ^^^^^^^^^^^^^^^^^^^^^
BrokenPipeError: [Errno 32] Broken pipe
2025-03-20 17:47:57,243 ERROR   MainThread:307683 [redirect.py:_on_write():661] error in stdout callback
Traceback (most recent call last):
  File "/home/inside-tech/Desktop/image_segmentation/.venv/lib/python3.12/site-packages/IPython/core/events.py", line 82, in trigger
    func(*args, **kwargs)
  File "/home/inside-tech/Desktop/image_segmentation/.venv/lib/python3.12/site-packages/wandb/sdk/wandb_init.py", line 570, in _resume_backend
    self.backend.interface.publish_resume()
  File "/home/inside-tech/Desktop/image_segmentation/.venv/lib/python3.12/site-packages/wandb/sdk/interface/interface.py", line 777, in publish_resume
    self._publish_resume(resume)
  File "/home/inside-tech/Desktop/image_segmentation/.venv/lib/python3.12/site-packages/wandb/sdk/interface/interface_shared.py", line 293, in _publish_resume
    self._publish(rec)
  File "/home/inside-tech/Desktop/image_segmentation/.venv/lib/python3.12/site-packages/wandb/sdk/interface/interface_sock.py", line 39, in _publish
    self._sock_client.send_record_publish(record)
  File "/home/inside-tech/Desktop/image_segmentation/.venv/lib/python3.12/site-packages/wandb/sdk/lib/sock_client.py", line 174, in send_record_publish
    self.send_server_request(server_req)
  File "/home/inside-tech/Desktop/image_segmentation/.venv/lib/python3.12/site-packages/wandb/sdk/lib/sock_client.py", line 154, in send_server_request
    self._send_message(msg)
  File "/home/inside-tech/Desktop/image_segmentation/.venv/lib/python3.12/site-packages/wandb/sdk/lib/sock_client.py", line 151, in _send_message
    self._sendall_with_error_handle(header + data)
  File "/home/inside-tech/Desktop/image_segmentation/.venv/lib/python3.12/site-packages/wandb/sdk/lib/sock_client.py", line 130, in _sendall_with_error_handle
    sent = self._sock.send(data)
           ^^^^^^^^^^^^^^^^^^^^^
BrokenPipeError: [Errno 32] Broken pipe

During handling of the above exception, another exception occurred:

Traceback (most recent call last):
  File "/home/inside-tech/Desktop/image_segmentation/.venv/lib/python3.12/site-packages/wandb/sdk/lib/redirect.py", line 659, in _on_write
    cb(written_data)
  File "/home/inside-tech/Desktop/image_segmentation/.venv/lib/python3.12/site-packages/wandb/sdk/wandb_run.py", line 2296, in <lambda>
    lambda data: self._console_raw_callback("stdout", data),
                 ^^^^^^^^^^^^^^^^^^^^^^^^^^^^^^^^^^^^^^^^^^
  File "/home/inside-tech/Desktop/image_segmentation/.venv/lib/python3.12/site-packages/wandb/sdk/wandb_run.py", line 401, in wrapper_fn
    return func(self, *args, **kwargs)
           ^^^^^^^^^^^^^^^^^^^^^^^^^^^
  File "/home/inside-tech/Desktop/image_segmentation/.venv/lib/python3.12/site-packages/wandb/sdk/wandb_run.py", line 1444, in _console_raw_callback
    self._backend.interface.publish_output_raw(name, data)
  File "/home/inside-tech/Desktop/image_segmentation/.venv/lib/python3.12/site-packages/wandb/sdk/interface/interface.py", line 761, in publish_output_raw
    self._publish_output_raw(o)
  File "/home/inside-tech/Desktop/image_segmentation/.venv/lib/python3.12/site-packages/wandb/sdk/interface/interface_shared.py", line 38, in _publish_output_raw
    self._publish(rec)
  File "/home/inside-tech/Desktop/image_segmentation/.venv/lib/python3.12/site-packages/wandb/sdk/interface/interface_sock.py", line 39, in _publish
    self._sock_client.send_record_publish(record)
  File "/home/inside-tech/Desktop/image_segmentation/.venv/lib/python3.12/site-packages/wandb/sdk/lib/sock_client.py", line 174, in send_record_publish
    self.send_server_request(server_req)
  File "/home/inside-tech/Desktop/image_segmentation/.venv/lib/python3.12/site-packages/wandb/sdk/lib/sock_client.py", line 154, in send_server_request
    self._send_message(msg)
  File "/home/inside-tech/Desktop/image_segmentation/.venv/lib/python3.12/site-packages/wandb/sdk/lib/sock_client.py", line 151, in _send_message
    self._sendall_with_error_handle(header + data)
  File "/home/inside-tech/Desktop/image_segmentation/.venv/lib/python3.12/site-packages/wandb/sdk/lib/sock_client.py", line 130, in _sendall_with_error_handle
    sent = self._sock.send(data)
           ^^^^^^^^^^^^^^^^^^^^^
BrokenPipeError: [Errno 32] Broken pipe
2025-03-20 17:47:57,289 INFO    MainThread:307683 [jupyter.py:save_ipynb():386] not saving jupyter notebook
2025-03-20 17:47:57,289 INFO    MainThread:307683 [wandb_init.py:_pause_backend():564] pausing backend
2025-03-20 17:47:57,290 ERROR   MainThread:307683 [redirect.py:_on_write():661] error in stdout callback
Traceback (most recent call last):
  File "/home/inside-tech/Desktop/image_segmentation/.venv/lib/python3.12/site-packages/IPython/core/events.py", line 82, in trigger
    func(*args, **kwargs)
  File "/home/inside-tech/Desktop/image_segmentation/.venv/lib/python3.12/site-packages/wandb/sdk/wandb_init.py", line 565, in _pause_backend
    self.backend.interface.publish_pause()
  File "/home/inside-tech/Desktop/image_segmentation/.venv/lib/python3.12/site-packages/wandb/sdk/interface/interface.py", line 769, in publish_pause
    self._publish_pause(pause)
  File "/home/inside-tech/Desktop/image_segmentation/.venv/lib/python3.12/site-packages/wandb/sdk/interface/interface_shared.py", line 289, in _publish_pause
    self._publish(rec)
  File "/home/inside-tech/Desktop/image_segmentation/.venv/lib/python3.12/site-packages/wandb/sdk/interface/interface_sock.py", line 39, in _publish
    self._sock_client.send_record_publish(record)
  File "/home/inside-tech/Desktop/image_segmentation/.venv/lib/python3.12/site-packages/wandb/sdk/lib/sock_client.py", line 174, in send_record_publish
    self.send_server_request(server_req)
  File "/home/inside-tech/Desktop/image_segmentation/.venv/lib/python3.12/site-packages/wandb/sdk/lib/sock_client.py", line 154, in send_server_request
    self._send_message(msg)
  File "/home/inside-tech/Desktop/image_segmentation/.venv/lib/python3.12/site-packages/wandb/sdk/lib/sock_client.py", line 151, in _send_message
    self._sendall_with_error_handle(header + data)
  File "/home/inside-tech/Desktop/image_segmentation/.venv/lib/python3.12/site-packages/wandb/sdk/lib/sock_client.py", line 130, in _sendall_with_error_handle
    sent = self._sock.send(data)
           ^^^^^^^^^^^^^^^^^^^^^
BrokenPipeError: [Errno 32] Broken pipe

During handling of the above exception, another exception occurred:

Traceback (most recent call last):
  File "/home/inside-tech/Desktop/image_segmentation/.venv/lib/python3.12/site-packages/wandb/sdk/lib/redirect.py", line 659, in _on_write
    cb(written_data)
  File "/home/inside-tech/Desktop/image_segmentation/.venv/lib/python3.12/site-packages/wandb/sdk/wandb_run.py", line 2296, in <lambda>
    lambda data: self._console_raw_callback("stdout", data),
                 ^^^^^^^^^^^^^^^^^^^^^^^^^^^^^^^^^^^^^^^^^^
  File "/home/inside-tech/Desktop/image_segmentation/.venv/lib/python3.12/site-packages/wandb/sdk/wandb_run.py", line 401, in wrapper_fn
    return func(self, *args, **kwargs)
           ^^^^^^^^^^^^^^^^^^^^^^^^^^^
  File "/home/inside-tech/Desktop/image_segmentation/.venv/lib/python3.12/site-packages/wandb/sdk/wandb_run.py", line 1444, in _console_raw_callback
    self._backend.interface.publish_output_raw(name, data)
  File "/home/inside-tech/Desktop/image_segmentation/.venv/lib/python3.12/site-packages/wandb/sdk/interface/interface.py", line 761, in publish_output_raw
    self._publish_output_raw(o)
  File "/home/inside-tech/Desktop/image_segmentation/.venv/lib/python3.12/site-packages/wandb/sdk/interface/interface_shared.py", line 38, in _publish_output_raw
    self._publish(rec)
  File "/home/inside-tech/Desktop/image_segmentation/.venv/lib/python3.12/site-packages/wandb/sdk/interface/interface_sock.py", line 39, in _publish
    self._sock_client.send_record_publish(record)
  File "/home/inside-tech/Desktop/image_segmentation/.venv/lib/python3.12/site-packages/wandb/sdk/lib/sock_client.py", line 174, in send_record_publish
    self.send_server_request(server_req)
  File "/home/inside-tech/Desktop/image_segmentation/.venv/lib/python3.12/site-packages/wandb/sdk/lib/sock_client.py", line 154, in send_server_request
    self._send_message(msg)
  File "/home/inside-tech/Desktop/image_segmentation/.venv/lib/python3.12/site-packages/wandb/sdk/lib/sock_client.py", line 151, in _send_message
    self._sendall_with_error_handle(header + data)
  File "/home/inside-tech/Desktop/image_segmentation/.venv/lib/python3.12/site-packages/wandb/sdk/lib/sock_client.py", line 130, in _sendall_with_error_handle
    sent = self._sock.send(data)
           ^^^^^^^^^^^^^^^^^^^^^
BrokenPipeError: [Errno 32] Broken pipe
2025-03-20 17:47:57,291 ERROR   MainThread:307683 [redirect.py:_on_write():661] error in stdout callback
Traceback (most recent call last):
  File "/home/inside-tech/Desktop/image_segmentation/.venv/lib/python3.12/site-packages/IPython/core/events.py", line 82, in trigger
    func(*args, **kwargs)
  File "/home/inside-tech/Desktop/image_segmentation/.venv/lib/python3.12/site-packages/wandb/sdk/wandb_init.py", line 565, in _pause_backend
    self.backend.interface.publish_pause()
  File "/home/inside-tech/Desktop/image_segmentation/.venv/lib/python3.12/site-packages/wandb/sdk/interface/interface.py", line 769, in publish_pause
    self._publish_pause(pause)
  File "/home/inside-tech/Desktop/image_segmentation/.venv/lib/python3.12/site-packages/wandb/sdk/interface/interface_shared.py", line 289, in _publish_pause
    self._publish(rec)
  File "/home/inside-tech/Desktop/image_segmentation/.venv/lib/python3.12/site-packages/wandb/sdk/interface/interface_sock.py", line 39, in _publish
    self._sock_client.send_record_publish(record)
  File "/home/inside-tech/Desktop/image_segmentation/.venv/lib/python3.12/site-packages/wandb/sdk/lib/sock_client.py", line 174, in send_record_publish
    self.send_server_request(server_req)
  File "/home/inside-tech/Desktop/image_segmentation/.venv/lib/python3.12/site-packages/wandb/sdk/lib/sock_client.py", line 154, in send_server_request
    self._send_message(msg)
  File "/home/inside-tech/Desktop/image_segmentation/.venv/lib/python3.12/site-packages/wandb/sdk/lib/sock_client.py", line 151, in _send_message
    self._sendall_with_error_handle(header + data)
  File "/home/inside-tech/Desktop/image_segmentation/.venv/lib/python3.12/site-packages/wandb/sdk/lib/sock_client.py", line 130, in _sendall_with_error_handle
    sent = self._sock.send(data)
           ^^^^^^^^^^^^^^^^^^^^^
BrokenPipeError: [Errno 32] Broken pipe

During handling of the above exception, another exception occurred:

Traceback (most recent call last):
  File "/home/inside-tech/Desktop/image_segmentation/.venv/lib/python3.12/site-packages/wandb/sdk/lib/redirect.py", line 659, in _on_write
    cb(written_data)
  File "/home/inside-tech/Desktop/image_segmentation/.venv/lib/python3.12/site-packages/wandb/sdk/wandb_run.py", line 2296, in <lambda>
    lambda data: self._console_raw_callback("stdout", data),
                 ^^^^^^^^^^^^^^^^^^^^^^^^^^^^^^^^^^^^^^^^^^
  File "/home/inside-tech/Desktop/image_segmentation/.venv/lib/python3.12/site-packages/wandb/sdk/wandb_run.py", line 401, in wrapper_fn
    return func(self, *args, **kwargs)
           ^^^^^^^^^^^^^^^^^^^^^^^^^^^
  File "/home/inside-tech/Desktop/image_segmentation/.venv/lib/python3.12/site-packages/wandb/sdk/wandb_run.py", line 1444, in _console_raw_callback
    self._backend.interface.publish_output_raw(name, data)
  File "/home/inside-tech/Desktop/image_segmentation/.venv/lib/python3.12/site-packages/wandb/sdk/interface/interface.py", line 761, in publish_output_raw
    self._publish_output_raw(o)
  File "/home/inside-tech/Desktop/image_segmentation/.venv/lib/python3.12/site-packages/wandb/sdk/interface/interface_shared.py", line 38, in _publish_output_raw
    self._publish(rec)
  File "/home/inside-tech/Desktop/image_segmentation/.venv/lib/python3.12/site-packages/wandb/sdk/interface/interface_sock.py", line 39, in _publish
    self._sock_client.send_record_publish(record)
  File "/home/inside-tech/Desktop/image_segmentation/.venv/lib/python3.12/site-packages/wandb/sdk/lib/sock_client.py", line 174, in send_record_publish
    self.send_server_request(server_req)
  File "/home/inside-tech/Desktop/image_segmentation/.venv/lib/python3.12/site-packages/wandb/sdk/lib/sock_client.py", line 154, in send_server_request
    self._send_message(msg)
  File "/home/inside-tech/Desktop/image_segmentation/.venv/lib/python3.12/site-packages/wandb/sdk/lib/sock_client.py", line 151, in _send_message
    self._sendall_with_error_handle(header + data)
  File "/home/inside-tech/Desktop/image_segmentation/.venv/lib/python3.12/site-packages/wandb/sdk/lib/sock_client.py", line 130, in _sendall_with_error_handle
    sent = self._sock.send(data)
           ^^^^^^^^^^^^^^^^^^^^^
BrokenPipeError: [Errno 32] Broken pipe
2025-03-20 17:47:57,341 INFO    MainThread:307683 [wandb_init.py:_resume_backend():569] resuming backend
2025-03-20 17:47:57,341 ERROR   MainThread:307683 [redirect.py:_on_write():661] error in stdout callback
Traceback (most recent call last):
  File "/home/inside-tech/Desktop/image_segmentation/.venv/lib/python3.12/site-packages/IPython/core/events.py", line 82, in trigger
    func(*args, **kwargs)
  File "/home/inside-tech/Desktop/image_segmentation/.venv/lib/python3.12/site-packages/wandb/sdk/wandb_init.py", line 570, in _resume_backend
    self.backend.interface.publish_resume()
  File "/home/inside-tech/Desktop/image_segmentation/.venv/lib/python3.12/site-packages/wandb/sdk/interface/interface.py", line 777, in publish_resume
    self._publish_resume(resume)
  File "/home/inside-tech/Desktop/image_segmentation/.venv/lib/python3.12/site-packages/wandb/sdk/interface/interface_shared.py", line 293, in _publish_resume
    self._publish(rec)
  File "/home/inside-tech/Desktop/image_segmentation/.venv/lib/python3.12/site-packages/wandb/sdk/interface/interface_sock.py", line 39, in _publish
    self._sock_client.send_record_publish(record)
  File "/home/inside-tech/Desktop/image_segmentation/.venv/lib/python3.12/site-packages/wandb/sdk/lib/sock_client.py", line 174, in send_record_publish
    self.send_server_request(server_req)
  File "/home/inside-tech/Desktop/image_segmentation/.venv/lib/python3.12/site-packages/wandb/sdk/lib/sock_client.py", line 154, in send_server_request
    self._send_message(msg)
  File "/home/inside-tech/Desktop/image_segmentation/.venv/lib/python3.12/site-packages/wandb/sdk/lib/sock_client.py", line 151, in _send_message
    self._sendall_with_error_handle(header + data)
  File "/home/inside-tech/Desktop/image_segmentation/.venv/lib/python3.12/site-packages/wandb/sdk/lib/sock_client.py", line 130, in _sendall_with_error_handle
    sent = self._sock.send(data)
           ^^^^^^^^^^^^^^^^^^^^^
BrokenPipeError: [Errno 32] Broken pipe

During handling of the above exception, another exception occurred:

Traceback (most recent call last):
  File "/home/inside-tech/Desktop/image_segmentation/.venv/lib/python3.12/site-packages/wandb/sdk/lib/redirect.py", line 659, in _on_write
    cb(written_data)
  File "/home/inside-tech/Desktop/image_segmentation/.venv/lib/python3.12/site-packages/wandb/sdk/wandb_run.py", line 2296, in <lambda>
    lambda data: self._console_raw_callback("stdout", data),
                 ^^^^^^^^^^^^^^^^^^^^^^^^^^^^^^^^^^^^^^^^^^
  File "/home/inside-tech/Desktop/image_segmentation/.venv/lib/python3.12/site-packages/wandb/sdk/wandb_run.py", line 401, in wrapper_fn
    return func(self, *args, **kwargs)
           ^^^^^^^^^^^^^^^^^^^^^^^^^^^
  File "/home/inside-tech/Desktop/image_segmentation/.venv/lib/python3.12/site-packages/wandb/sdk/wandb_run.py", line 1444, in _console_raw_callback
    self._backend.interface.publish_output_raw(name, data)
  File "/home/inside-tech/Desktop/image_segmentation/.venv/lib/python3.12/site-packages/wandb/sdk/interface/interface.py", line 761, in publish_output_raw
    self._publish_output_raw(o)
  File "/home/inside-tech/Desktop/image_segmentation/.venv/lib/python3.12/site-packages/wandb/sdk/interface/interface_shared.py", line 38, in _publish_output_raw
    self._publish(rec)
  File "/home/inside-tech/Desktop/image_segmentation/.venv/lib/python3.12/site-packages/wandb/sdk/interface/interface_sock.py", line 39, in _publish
    self._sock_client.send_record_publish(record)
  File "/home/inside-tech/Desktop/image_segmentation/.venv/lib/python3.12/site-packages/wandb/sdk/lib/sock_client.py", line 174, in send_record_publish
    self.send_server_request(server_req)
  File "/home/inside-tech/Desktop/image_segmentation/.venv/lib/python3.12/site-packages/wandb/sdk/lib/sock_client.py", line 154, in send_server_request
    self._send_message(msg)
  File "/home/inside-tech/Desktop/image_segmentation/.venv/lib/python3.12/site-packages/wandb/sdk/lib/sock_client.py", line 151, in _send_message
    self._sendall_with_error_handle(header + data)
  File "/home/inside-tech/Desktop/image_segmentation/.venv/lib/python3.12/site-packages/wandb/sdk/lib/sock_client.py", line 130, in _sendall_with_error_handle
    sent = self._sock.send(data)
           ^^^^^^^^^^^^^^^^^^^^^
BrokenPipeError: [Errno 32] Broken pipe
2025-03-20 17:47:57,342 ERROR   MainThread:307683 [redirect.py:_on_write():661] error in stdout callback
Traceback (most recent call last):
  File "/home/inside-tech/Desktop/image_segmentation/.venv/lib/python3.12/site-packages/IPython/core/events.py", line 82, in trigger
    func(*args, **kwargs)
  File "/home/inside-tech/Desktop/image_segmentation/.venv/lib/python3.12/site-packages/wandb/sdk/wandb_init.py", line 570, in _resume_backend
    self.backend.interface.publish_resume()
  File "/home/inside-tech/Desktop/image_segmentation/.venv/lib/python3.12/site-packages/wandb/sdk/interface/interface.py", line 777, in publish_resume
    self._publish_resume(resume)
  File "/home/inside-tech/Desktop/image_segmentation/.venv/lib/python3.12/site-packages/wandb/sdk/interface/interface_shared.py", line 293, in _publish_resume
    self._publish(rec)
  File "/home/inside-tech/Desktop/image_segmentation/.venv/lib/python3.12/site-packages/wandb/sdk/interface/interface_sock.py", line 39, in _publish
    self._sock_client.send_record_publish(record)
  File "/home/inside-tech/Desktop/image_segmentation/.venv/lib/python3.12/site-packages/wandb/sdk/lib/sock_client.py", line 174, in send_record_publish
    self.send_server_request(server_req)
  File "/home/inside-tech/Desktop/image_segmentation/.venv/lib/python3.12/site-packages/wandb/sdk/lib/sock_client.py", line 154, in send_server_request
    self._send_message(msg)
  File "/home/inside-tech/Desktop/image_segmentation/.venv/lib/python3.12/site-packages/wandb/sdk/lib/sock_client.py", line 151, in _send_message
    self._sendall_with_error_handle(header + data)
  File "/home/inside-tech/Desktop/image_segmentation/.venv/lib/python3.12/site-packages/wandb/sdk/lib/sock_client.py", line 130, in _sendall_with_error_handle
    sent = self._sock.send(data)
           ^^^^^^^^^^^^^^^^^^^^^
BrokenPipeError: [Errno 32] Broken pipe

During handling of the above exception, another exception occurred:

Traceback (most recent call last):
  File "/home/inside-tech/Desktop/image_segmentation/.venv/lib/python3.12/site-packages/wandb/sdk/lib/redirect.py", line 659, in _on_write
    cb(written_data)
  File "/home/inside-tech/Desktop/image_segmentation/.venv/lib/python3.12/site-packages/wandb/sdk/wandb_run.py", line 2296, in <lambda>
    lambda data: self._console_raw_callback("stdout", data),
                 ^^^^^^^^^^^^^^^^^^^^^^^^^^^^^^^^^^^^^^^^^^
  File "/home/inside-tech/Desktop/image_segmentation/.venv/lib/python3.12/site-packages/wandb/sdk/wandb_run.py", line 401, in wrapper_fn
    return func(self, *args, **kwargs)
           ^^^^^^^^^^^^^^^^^^^^^^^^^^^
  File "/home/inside-tech/Desktop/image_segmentation/.venv/lib/python3.12/site-packages/wandb/sdk/wandb_run.py", line 1444, in _console_raw_callback
    self._backend.interface.publish_output_raw(name, data)
  File "/home/inside-tech/Desktop/image_segmentation/.venv/lib/python3.12/site-packages/wandb/sdk/interface/interface.py", line 761, in publish_output_raw
    self._publish_output_raw(o)
  File "/home/inside-tech/Desktop/image_segmentation/.venv/lib/python3.12/site-packages/wandb/sdk/interface/interface_shared.py", line 38, in _publish_output_raw
    self._publish(rec)
  File "/home/inside-tech/Desktop/image_segmentation/.venv/lib/python3.12/site-packages/wandb/sdk/interface/interface_sock.py", line 39, in _publish
    self._sock_client.send_record_publish(record)
  File "/home/inside-tech/Desktop/image_segmentation/.venv/lib/python3.12/site-packages/wandb/sdk/lib/sock_client.py", line 174, in send_record_publish
    self.send_server_request(server_req)
  File "/home/inside-tech/Desktop/image_segmentation/.venv/lib/python3.12/site-packages/wandb/sdk/lib/sock_client.py", line 154, in send_server_request
    self._send_message(msg)
  File "/home/inside-tech/Desktop/image_segmentation/.venv/lib/python3.12/site-packages/wandb/sdk/lib/sock_client.py", line 151, in _send_message
    self._sendall_with_error_handle(header + data)
  File "/home/inside-tech/Desktop/image_segmentation/.venv/lib/python3.12/site-packages/wandb/sdk/lib/sock_client.py", line 130, in _sendall_with_error_handle
    sent = self._sock.send(data)
           ^^^^^^^^^^^^^^^^^^^^^
BrokenPipeError: [Errno 32] Broken pipe
2025-03-20 17:47:57,389 INFO    MainThread:307683 [jupyter.py:save_ipynb():386] not saving jupyter notebook
2025-03-20 17:47:57,390 INFO    MainThread:307683 [wandb_init.py:_pause_backend():564] pausing backend
2025-03-20 17:47:57,390 ERROR   MainThread:307683 [redirect.py:_on_write():661] error in stdout callback
Traceback (most recent call last):
  File "/home/inside-tech/Desktop/image_segmentation/.venv/lib/python3.12/site-packages/IPython/core/events.py", line 82, in trigger
    func(*args, **kwargs)
  File "/home/inside-tech/Desktop/image_segmentation/.venv/lib/python3.12/site-packages/wandb/sdk/wandb_init.py", line 565, in _pause_backend
    self.backend.interface.publish_pause()
  File "/home/inside-tech/Desktop/image_segmentation/.venv/lib/python3.12/site-packages/wandb/sdk/interface/interface.py", line 769, in publish_pause
    self._publish_pause(pause)
  File "/home/inside-tech/Desktop/image_segmentation/.venv/lib/python3.12/site-packages/wandb/sdk/interface/interface_shared.py", line 289, in _publish_pause
    self._publish(rec)
  File "/home/inside-tech/Desktop/image_segmentation/.venv/lib/python3.12/site-packages/wandb/sdk/interface/interface_sock.py", line 39, in _publish
    self._sock_client.send_record_publish(record)
  File "/home/inside-tech/Desktop/image_segmentation/.venv/lib/python3.12/site-packages/wandb/sdk/lib/sock_client.py", line 174, in send_record_publish
    self.send_server_request(server_req)
  File "/home/inside-tech/Desktop/image_segmentation/.venv/lib/python3.12/site-packages/wandb/sdk/lib/sock_client.py", line 154, in send_server_request
    self._send_message(msg)
  File "/home/inside-tech/Desktop/image_segmentation/.venv/lib/python3.12/site-packages/wandb/sdk/lib/sock_client.py", line 151, in _send_message
    self._sendall_with_error_handle(header + data)
  File "/home/inside-tech/Desktop/image_segmentation/.venv/lib/python3.12/site-packages/wandb/sdk/lib/sock_client.py", line 130, in _sendall_with_error_handle
    sent = self._sock.send(data)
           ^^^^^^^^^^^^^^^^^^^^^
BrokenPipeError: [Errno 32] Broken pipe

During handling of the above exception, another exception occurred:

Traceback (most recent call last):
  File "/home/inside-tech/Desktop/image_segmentation/.venv/lib/python3.12/site-packages/wandb/sdk/lib/redirect.py", line 659, in _on_write
    cb(written_data)
  File "/home/inside-tech/Desktop/image_segmentation/.venv/lib/python3.12/site-packages/wandb/sdk/wandb_run.py", line 2296, in <lambda>
    lambda data: self._console_raw_callback("stdout", data),
                 ^^^^^^^^^^^^^^^^^^^^^^^^^^^^^^^^^^^^^^^^^^
  File "/home/inside-tech/Desktop/image_segmentation/.venv/lib/python3.12/site-packages/wandb/sdk/wandb_run.py", line 401, in wrapper_fn
    return func(self, *args, **kwargs)
           ^^^^^^^^^^^^^^^^^^^^^^^^^^^
  File "/home/inside-tech/Desktop/image_segmentation/.venv/lib/python3.12/site-packages/wandb/sdk/wandb_run.py", line 1444, in _console_raw_callback
    self._backend.interface.publish_output_raw(name, data)
  File "/home/inside-tech/Desktop/image_segmentation/.venv/lib/python3.12/site-packages/wandb/sdk/interface/interface.py", line 761, in publish_output_raw
    self._publish_output_raw(o)
  File "/home/inside-tech/Desktop/image_segmentation/.venv/lib/python3.12/site-packages/wandb/sdk/interface/interface_shared.py", line 38, in _publish_output_raw
    self._publish(rec)
  File "/home/inside-tech/Desktop/image_segmentation/.venv/lib/python3.12/site-packages/wandb/sdk/interface/interface_sock.py", line 39, in _publish
    self._sock_client.send_record_publish(record)
  File "/home/inside-tech/Desktop/image_segmentation/.venv/lib/python3.12/site-packages/wandb/sdk/lib/sock_client.py", line 174, in send_record_publish
    self.send_server_request(server_req)
  File "/home/inside-tech/Desktop/image_segmentation/.venv/lib/python3.12/site-packages/wandb/sdk/lib/sock_client.py", line 154, in send_server_request
    self._send_message(msg)
  File "/home/inside-tech/Desktop/image_segmentation/.venv/lib/python3.12/site-packages/wandb/sdk/lib/sock_client.py", line 151, in _send_message
    self._sendall_with_error_handle(header + data)
  File "/home/inside-tech/Desktop/image_segmentation/.venv/lib/python3.12/site-packages/wandb/sdk/lib/sock_client.py", line 130, in _sendall_with_error_handle
    sent = self._sock.send(data)
           ^^^^^^^^^^^^^^^^^^^^^
BrokenPipeError: [Errno 32] Broken pipe
2025-03-20 17:47:57,390 ERROR   MainThread:307683 [redirect.py:_on_write():661] error in stdout callback
Traceback (most recent call last):
  File "/home/inside-tech/Desktop/image_segmentation/.venv/lib/python3.12/site-packages/IPython/core/events.py", line 82, in trigger
    func(*args, **kwargs)
  File "/home/inside-tech/Desktop/image_segmentation/.venv/lib/python3.12/site-packages/wandb/sdk/wandb_init.py", line 565, in _pause_backend
    self.backend.interface.publish_pause()
  File "/home/inside-tech/Desktop/image_segmentation/.venv/lib/python3.12/site-packages/wandb/sdk/interface/interface.py", line 769, in publish_pause
    self._publish_pause(pause)
  File "/home/inside-tech/Desktop/image_segmentation/.venv/lib/python3.12/site-packages/wandb/sdk/interface/interface_shared.py", line 289, in _publish_pause
    self._publish(rec)
  File "/home/inside-tech/Desktop/image_segmentation/.venv/lib/python3.12/site-packages/wandb/sdk/interface/interface_sock.py", line 39, in _publish
    self._sock_client.send_record_publish(record)
  File "/home/inside-tech/Desktop/image_segmentation/.venv/lib/python3.12/site-packages/wandb/sdk/lib/sock_client.py", line 174, in send_record_publish
    self.send_server_request(server_req)
  File "/home/inside-tech/Desktop/image_segmentation/.venv/lib/python3.12/site-packages/wandb/sdk/lib/sock_client.py", line 154, in send_server_request
    self._send_message(msg)
  File "/home/inside-tech/Desktop/image_segmentation/.venv/lib/python3.12/site-packages/wandb/sdk/lib/sock_client.py", line 151, in _send_message
    self._sendall_with_error_handle(header + data)
  File "/home/inside-tech/Desktop/image_segmentation/.venv/lib/python3.12/site-packages/wandb/sdk/lib/sock_client.py", line 130, in _sendall_with_error_handle
    sent = self._sock.send(data)
           ^^^^^^^^^^^^^^^^^^^^^
BrokenPipeError: [Errno 32] Broken pipe

During handling of the above exception, another exception occurred:

Traceback (most recent call last):
  File "/home/inside-tech/Desktop/image_segmentation/.venv/lib/python3.12/site-packages/wandb/sdk/lib/redirect.py", line 659, in _on_write
    cb(written_data)
  File "/home/inside-tech/Desktop/image_segmentation/.venv/lib/python3.12/site-packages/wandb/sdk/wandb_run.py", line 2296, in <lambda>
    lambda data: self._console_raw_callback("stdout", data),
                 ^^^^^^^^^^^^^^^^^^^^^^^^^^^^^^^^^^^^^^^^^^
  File "/home/inside-tech/Desktop/image_segmentation/.venv/lib/python3.12/site-packages/wandb/sdk/wandb_run.py", line 401, in wrapper_fn
    return func(self, *args, **kwargs)
           ^^^^^^^^^^^^^^^^^^^^^^^^^^^
  File "/home/inside-tech/Desktop/image_segmentation/.venv/lib/python3.12/site-packages/wandb/sdk/wandb_run.py", line 1444, in _console_raw_callback
    self._backend.interface.publish_output_raw(name, data)
  File "/home/inside-tech/Desktop/image_segmentation/.venv/lib/python3.12/site-packages/wandb/sdk/interface/interface.py", line 761, in publish_output_raw
    self._publish_output_raw(o)
  File "/home/inside-tech/Desktop/image_segmentation/.venv/lib/python3.12/site-packages/wandb/sdk/interface/interface_shared.py", line 38, in _publish_output_raw
    self._publish(rec)
  File "/home/inside-tech/Desktop/image_segmentation/.venv/lib/python3.12/site-packages/wandb/sdk/interface/interface_sock.py", line 39, in _publish
    self._sock_client.send_record_publish(record)
  File "/home/inside-tech/Desktop/image_segmentation/.venv/lib/python3.12/site-packages/wandb/sdk/lib/sock_client.py", line 174, in send_record_publish
    self.send_server_request(server_req)
  File "/home/inside-tech/Desktop/image_segmentation/.venv/lib/python3.12/site-packages/wandb/sdk/lib/sock_client.py", line 154, in send_server_request
    self._send_message(msg)
  File "/home/inside-tech/Desktop/image_segmentation/.venv/lib/python3.12/site-packages/wandb/sdk/lib/sock_client.py", line 151, in _send_message
    self._sendall_with_error_handle(header + data)
  File "/home/inside-tech/Desktop/image_segmentation/.venv/lib/python3.12/site-packages/wandb/sdk/lib/sock_client.py", line 130, in _sendall_with_error_handle
    sent = self._sock.send(data)
           ^^^^^^^^^^^^^^^^^^^^^
BrokenPipeError: [Errno 32] Broken pipe
2025-03-20 17:47:57,440 INFO    MainThread:307683 [wandb_init.py:_resume_backend():569] resuming backend
2025-03-20 17:47:57,440 ERROR   MainThread:307683 [redirect.py:_on_write():661] error in stdout callback
Traceback (most recent call last):
  File "/home/inside-tech/Desktop/image_segmentation/.venv/lib/python3.12/site-packages/IPython/core/events.py", line 82, in trigger
    func(*args, **kwargs)
  File "/home/inside-tech/Desktop/image_segmentation/.venv/lib/python3.12/site-packages/wandb/sdk/wandb_init.py", line 570, in _resume_backend
    self.backend.interface.publish_resume()
  File "/home/inside-tech/Desktop/image_segmentation/.venv/lib/python3.12/site-packages/wandb/sdk/interface/interface.py", line 777, in publish_resume
    self._publish_resume(resume)
  File "/home/inside-tech/Desktop/image_segmentation/.venv/lib/python3.12/site-packages/wandb/sdk/interface/interface_shared.py", line 293, in _publish_resume
    self._publish(rec)
  File "/home/inside-tech/Desktop/image_segmentation/.venv/lib/python3.12/site-packages/wandb/sdk/interface/interface_sock.py", line 39, in _publish
    self._sock_client.send_record_publish(record)
  File "/home/inside-tech/Desktop/image_segmentation/.venv/lib/python3.12/site-packages/wandb/sdk/lib/sock_client.py", line 174, in send_record_publish
    self.send_server_request(server_req)
  File "/home/inside-tech/Desktop/image_segmentation/.venv/lib/python3.12/site-packages/wandb/sdk/lib/sock_client.py", line 154, in send_server_request
    self._send_message(msg)
  File "/home/inside-tech/Desktop/image_segmentation/.venv/lib/python3.12/site-packages/wandb/sdk/lib/sock_client.py", line 151, in _send_message
    self._sendall_with_error_handle(header + data)
  File "/home/inside-tech/Desktop/image_segmentation/.venv/lib/python3.12/site-packages/wandb/sdk/lib/sock_client.py", line 130, in _sendall_with_error_handle
    sent = self._sock.send(data)
           ^^^^^^^^^^^^^^^^^^^^^
BrokenPipeError: [Errno 32] Broken pipe

During handling of the above exception, another exception occurred:

Traceback (most recent call last):
  File "/home/inside-tech/Desktop/image_segmentation/.venv/lib/python3.12/site-packages/wandb/sdk/lib/redirect.py", line 659, in _on_write
    cb(written_data)
  File "/home/inside-tech/Desktop/image_segmentation/.venv/lib/python3.12/site-packages/wandb/sdk/wandb_run.py", line 2296, in <lambda>
    lambda data: self._console_raw_callback("stdout", data),
                 ^^^^^^^^^^^^^^^^^^^^^^^^^^^^^^^^^^^^^^^^^^
  File "/home/inside-tech/Desktop/image_segmentation/.venv/lib/python3.12/site-packages/wandb/sdk/wandb_run.py", line 401, in wrapper_fn
    return func(self, *args, **kwargs)
           ^^^^^^^^^^^^^^^^^^^^^^^^^^^
  File "/home/inside-tech/Desktop/image_segmentation/.venv/lib/python3.12/site-packages/wandb/sdk/wandb_run.py", line 1444, in _console_raw_callback
    self._backend.interface.publish_output_raw(name, data)
  File "/home/inside-tech/Desktop/image_segmentation/.venv/lib/python3.12/site-packages/wandb/sdk/interface/interface.py", line 761, in publish_output_raw
    self._publish_output_raw(o)
  File "/home/inside-tech/Desktop/image_segmentation/.venv/lib/python3.12/site-packages/wandb/sdk/interface/interface_shared.py", line 38, in _publish_output_raw
    self._publish(rec)
  File "/home/inside-tech/Desktop/image_segmentation/.venv/lib/python3.12/site-packages/wandb/sdk/interface/interface_sock.py", line 39, in _publish
    self._sock_client.send_record_publish(record)
  File "/home/inside-tech/Desktop/image_segmentation/.venv/lib/python3.12/site-packages/wandb/sdk/lib/sock_client.py", line 174, in send_record_publish
    self.send_server_request(server_req)
  File "/home/inside-tech/Desktop/image_segmentation/.venv/lib/python3.12/site-packages/wandb/sdk/lib/sock_client.py", line 154, in send_server_request
    self._send_message(msg)
  File "/home/inside-tech/Desktop/image_segmentation/.venv/lib/python3.12/site-packages/wandb/sdk/lib/sock_client.py", line 151, in _send_message
    self._sendall_with_error_handle(header + data)
  File "/home/inside-tech/Desktop/image_segmentation/.venv/lib/python3.12/site-packages/wandb/sdk/lib/sock_client.py", line 130, in _sendall_with_error_handle
    sent = self._sock.send(data)
           ^^^^^^^^^^^^^^^^^^^^^
BrokenPipeError: [Errno 32] Broken pipe
2025-03-20 17:47:57,441 ERROR   MainThread:307683 [redirect.py:_on_write():661] error in stdout callback
Traceback (most recent call last):
  File "/home/inside-tech/Desktop/image_segmentation/.venv/lib/python3.12/site-packages/IPython/core/events.py", line 82, in trigger
    func(*args, **kwargs)
  File "/home/inside-tech/Desktop/image_segmentation/.venv/lib/python3.12/site-packages/wandb/sdk/wandb_init.py", line 570, in _resume_backend
    self.backend.interface.publish_resume()
  File "/home/inside-tech/Desktop/image_segmentation/.venv/lib/python3.12/site-packages/wandb/sdk/interface/interface.py", line 777, in publish_resume
    self._publish_resume(resume)
  File "/home/inside-tech/Desktop/image_segmentation/.venv/lib/python3.12/site-packages/wandb/sdk/interface/interface_shared.py", line 293, in _publish_resume
    self._publish(rec)
  File "/home/inside-tech/Desktop/image_segmentation/.venv/lib/python3.12/site-packages/wandb/sdk/interface/interface_sock.py", line 39, in _publish
    self._sock_client.send_record_publish(record)
  File "/home/inside-tech/Desktop/image_segmentation/.venv/lib/python3.12/site-packages/wandb/sdk/lib/sock_client.py", line 174, in send_record_publish
    self.send_server_request(server_req)
  File "/home/inside-tech/Desktop/image_segmentation/.venv/lib/python3.12/site-packages/wandb/sdk/lib/sock_client.py", line 154, in send_server_request
    self._send_message(msg)
  File "/home/inside-tech/Desktop/image_segmentation/.venv/lib/python3.12/site-packages/wandb/sdk/lib/sock_client.py", line 151, in _send_message
    self._sendall_with_error_handle(header + data)
  File "/home/inside-tech/Desktop/image_segmentation/.venv/lib/python3.12/site-packages/wandb/sdk/lib/sock_client.py", line 130, in _sendall_with_error_handle
    sent = self._sock.send(data)
           ^^^^^^^^^^^^^^^^^^^^^
BrokenPipeError: [Errno 32] Broken pipe

During handling of the above exception, another exception occurred:

Traceback (most recent call last):
  File "/home/inside-tech/Desktop/image_segmentation/.venv/lib/python3.12/site-packages/wandb/sdk/lib/redirect.py", line 659, in _on_write
    cb(written_data)
  File "/home/inside-tech/Desktop/image_segmentation/.venv/lib/python3.12/site-packages/wandb/sdk/wandb_run.py", line 2296, in <lambda>
    lambda data: self._console_raw_callback("stdout", data),
                 ^^^^^^^^^^^^^^^^^^^^^^^^^^^^^^^^^^^^^^^^^^
  File "/home/inside-tech/Desktop/image_segmentation/.venv/lib/python3.12/site-packages/wandb/sdk/wandb_run.py", line 401, in wrapper_fn
    return func(self, *args, **kwargs)
           ^^^^^^^^^^^^^^^^^^^^^^^^^^^
  File "/home/inside-tech/Desktop/image_segmentation/.venv/lib/python3.12/site-packages/wandb/sdk/wandb_run.py", line 1444, in _console_raw_callback
    self._backend.interface.publish_output_raw(name, data)
  File "/home/inside-tech/Desktop/image_segmentation/.venv/lib/python3.12/site-packages/wandb/sdk/interface/interface.py", line 761, in publish_output_raw
    self._publish_output_raw(o)
  File "/home/inside-tech/Desktop/image_segmentation/.venv/lib/python3.12/site-packages/wandb/sdk/interface/interface_shared.py", line 38, in _publish_output_raw
    self._publish(rec)
  File "/home/inside-tech/Desktop/image_segmentation/.venv/lib/python3.12/site-packages/wandb/sdk/interface/interface_sock.py", line 39, in _publish
    self._sock_client.send_record_publish(record)
  File "/home/inside-tech/Desktop/image_segmentation/.venv/lib/python3.12/site-packages/wandb/sdk/lib/sock_client.py", line 174, in send_record_publish
    self.send_server_request(server_req)
  File "/home/inside-tech/Desktop/image_segmentation/.venv/lib/python3.12/site-packages/wandb/sdk/lib/sock_client.py", line 154, in send_server_request
    self._send_message(msg)
  File "/home/inside-tech/Desktop/image_segmentation/.venv/lib/python3.12/site-packages/wandb/sdk/lib/sock_client.py", line 151, in _send_message
    self._sendall_with_error_handle(header + data)
  File "/home/inside-tech/Desktop/image_segmentation/.venv/lib/python3.12/site-packages/wandb/sdk/lib/sock_client.py", line 130, in _sendall_with_error_handle
    sent = self._sock.send(data)
           ^^^^^^^^^^^^^^^^^^^^^
BrokenPipeError: [Errno 32] Broken pipe
2025-03-20 17:47:57,489 INFO    MainThread:307683 [wandb_init.py:setup_run_log_directory():647] Logging user logs to /home/inside-tech/Desktop/image_segmentation/wandb/run-20250320_174757-4icihnpy/logs/debug.log
2025-03-20 17:47:57,489 INFO    MainThread:307683 [wandb_init.py:setup_run_log_directory():648] Logging internal logs to /home/inside-tech/Desktop/image_segmentation/wandb/run-20250320_174757-4icihnpy/logs/debug-internal.log
2025-03-20 17:47:57,489 INFO    MainThread:307683 [wandb_init.py:init():761] calling init triggers
2025-03-20 17:47:57,489 INFO    MainThread:307683 [wandb_init.py:init():766] wandb.init called with sweep_config: {}
config: {'_wandb': {}}
2025-03-20 17:47:57,489 INFO    MainThread:307683 [wandb_init.py:init():776] wandb.init() called while a run is active
2025-03-20 17:47:57,489 ERROR   MainThread:307683 [wandb_init.py:init():1478] error in wandb.init()
Traceback (most recent call last):
  File "/home/inside-tech/Desktop/image_segmentation/.venv/lib/python3.12/site-packages/wandb/sdk/wandb_init.py", line 1468, in init
    return wi.init(run_settings, run_config)
           ^^^^^^^^^^^^^^^^^^^^^^^^^^^^^^^^^
  File "/home/inside-tech/Desktop/image_segmentation/.venv/lib/python3.12/site-packages/wandb/sdk/wandb_init.py", line 779, in init
    with telemetry.context() as tel:
  File "/home/inside-tech/Desktop/image_segmentation/.venv/lib/python3.12/site-packages/wandb/sdk/lib/telemetry.py", line 42, in __exit__
    self._run._telemetry_callback(self._obj)
  File "/home/inside-tech/Desktop/image_segmentation/.venv/lib/python3.12/site-packages/wandb/sdk/wandb_run.py", line 749, in _telemetry_callback
    self._telemetry_flush()
  File "/home/inside-tech/Desktop/image_segmentation/.venv/lib/python3.12/site-packages/wandb/sdk/wandb_run.py", line 762, in _telemetry_flush
    self._backend.interface._publish_telemetry(self._telemetry_obj)
  File "/home/inside-tech/Desktop/image_segmentation/.venv/lib/python3.12/site-packages/wandb/sdk/interface/interface_shared.py", line 60, in _publish_telemetry
    self._publish(rec)
  File "/home/inside-tech/Desktop/image_segmentation/.venv/lib/python3.12/site-packages/wandb/sdk/interface/interface_sock.py", line 39, in _publish
    self._sock_client.send_record_publish(record)
  File "/home/inside-tech/Desktop/image_segmentation/.venv/lib/python3.12/site-packages/wandb/sdk/lib/sock_client.py", line 174, in send_record_publish
    self.send_server_request(server_req)
  File "/home/inside-tech/Desktop/image_segmentation/.venv/lib/python3.12/site-packages/wandb/sdk/lib/sock_client.py", line 154, in send_server_request
    self._send_message(msg)
  File "/home/inside-tech/Desktop/image_segmentation/.venv/lib/python3.12/site-packages/wandb/sdk/lib/sock_client.py", line 151, in _send_message
    self._sendall_with_error_handle(header + data)
  File "/home/inside-tech/Desktop/image_segmentation/.venv/lib/python3.12/site-packages/wandb/sdk/lib/sock_client.py", line 130, in _sendall_with_error_handle
    sent = self._sock.send(data)
           ^^^^^^^^^^^^^^^^^^^^^
BrokenPipeError: [Errno 32] Broken pipe
2025-03-20 17:47:57,675 INFO    MainThread:307683 [jupyter.py:save_ipynb():386] not saving jupyter notebook
2025-03-20 17:47:57,676 INFO    MainThread:307683 [wandb_init.py:_pause_backend():564] pausing backend
2025-03-20 17:47:57,676 ERROR   MainThread:307683 [redirect.py:_on_write():661] error in stdout callback
Traceback (most recent call last):
  File "/home/inside-tech/Desktop/image_segmentation/.venv/lib/python3.12/site-packages/IPython/core/events.py", line 82, in trigger
    func(*args, **kwargs)
  File "/home/inside-tech/Desktop/image_segmentation/.venv/lib/python3.12/site-packages/wandb/sdk/wandb_init.py", line 565, in _pause_backend
    self.backend.interface.publish_pause()
  File "/home/inside-tech/Desktop/image_segmentation/.venv/lib/python3.12/site-packages/wandb/sdk/interface/interface.py", line 769, in publish_pause
    self._publish_pause(pause)
  File "/home/inside-tech/Desktop/image_segmentation/.venv/lib/python3.12/site-packages/wandb/sdk/interface/interface_shared.py", line 289, in _publish_pause
    self._publish(rec)
  File "/home/inside-tech/Desktop/image_segmentation/.venv/lib/python3.12/site-packages/wandb/sdk/interface/interface_sock.py", line 39, in _publish
    self._sock_client.send_record_publish(record)
  File "/home/inside-tech/Desktop/image_segmentation/.venv/lib/python3.12/site-packages/wandb/sdk/lib/sock_client.py", line 174, in send_record_publish
    self.send_server_request(server_req)
  File "/home/inside-tech/Desktop/image_segmentation/.venv/lib/python3.12/site-packages/wandb/sdk/lib/sock_client.py", line 154, in send_server_request
    self._send_message(msg)
  File "/home/inside-tech/Desktop/image_segmentation/.venv/lib/python3.12/site-packages/wandb/sdk/lib/sock_client.py", line 151, in _send_message
    self._sendall_with_error_handle(header + data)
  File "/home/inside-tech/Desktop/image_segmentation/.venv/lib/python3.12/site-packages/wandb/sdk/lib/sock_client.py", line 130, in _sendall_with_error_handle
    sent = self._sock.send(data)
           ^^^^^^^^^^^^^^^^^^^^^
BrokenPipeError: [Errno 32] Broken pipe

During handling of the above exception, another exception occurred:

Traceback (most recent call last):
  File "/home/inside-tech/Desktop/image_segmentation/.venv/lib/python3.12/site-packages/wandb/sdk/lib/redirect.py", line 659, in _on_write
    cb(written_data)
  File "/home/inside-tech/Desktop/image_segmentation/.venv/lib/python3.12/site-packages/wandb/sdk/wandb_run.py", line 2296, in <lambda>
    lambda data: self._console_raw_callback("stdout", data),
                 ^^^^^^^^^^^^^^^^^^^^^^^^^^^^^^^^^^^^^^^^^^
  File "/home/inside-tech/Desktop/image_segmentation/.venv/lib/python3.12/site-packages/wandb/sdk/wandb_run.py", line 401, in wrapper_fn
    return func(self, *args, **kwargs)
           ^^^^^^^^^^^^^^^^^^^^^^^^^^^
  File "/home/inside-tech/Desktop/image_segmentation/.venv/lib/python3.12/site-packages/wandb/sdk/wandb_run.py", line 1444, in _console_raw_callback
    self._backend.interface.publish_output_raw(name, data)
  File "/home/inside-tech/Desktop/image_segmentation/.venv/lib/python3.12/site-packages/wandb/sdk/interface/interface.py", line 761, in publish_output_raw
    self._publish_output_raw(o)
  File "/home/inside-tech/Desktop/image_segmentation/.venv/lib/python3.12/site-packages/wandb/sdk/interface/interface_shared.py", line 38, in _publish_output_raw
    self._publish(rec)
  File "/home/inside-tech/Desktop/image_segmentation/.venv/lib/python3.12/site-packages/wandb/sdk/interface/interface_sock.py", line 39, in _publish
    self._sock_client.send_record_publish(record)
  File "/home/inside-tech/Desktop/image_segmentation/.venv/lib/python3.12/site-packages/wandb/sdk/lib/sock_client.py", line 174, in send_record_publish
    self.send_server_request(server_req)
  File "/home/inside-tech/Desktop/image_segmentation/.venv/lib/python3.12/site-packages/wandb/sdk/lib/sock_client.py", line 154, in send_server_request
    self._send_message(msg)
  File "/home/inside-tech/Desktop/image_segmentation/.venv/lib/python3.12/site-packages/wandb/sdk/lib/sock_client.py", line 151, in _send_message
    self._sendall_with_error_handle(header + data)
  File "/home/inside-tech/Desktop/image_segmentation/.venv/lib/python3.12/site-packages/wandb/sdk/lib/sock_client.py", line 130, in _sendall_with_error_handle
    sent = self._sock.send(data)
           ^^^^^^^^^^^^^^^^^^^^^
BrokenPipeError: [Errno 32] Broken pipe
2025-03-20 17:47:57,676 ERROR   MainThread:307683 [redirect.py:_on_write():661] error in stdout callback
Traceback (most recent call last):
  File "/home/inside-tech/Desktop/image_segmentation/.venv/lib/python3.12/site-packages/IPython/core/events.py", line 82, in trigger
    func(*args, **kwargs)
  File "/home/inside-tech/Desktop/image_segmentation/.venv/lib/python3.12/site-packages/wandb/sdk/wandb_init.py", line 565, in _pause_backend
    self.backend.interface.publish_pause()
  File "/home/inside-tech/Desktop/image_segmentation/.venv/lib/python3.12/site-packages/wandb/sdk/interface/interface.py", line 769, in publish_pause
    self._publish_pause(pause)
  File "/home/inside-tech/Desktop/image_segmentation/.venv/lib/python3.12/site-packages/wandb/sdk/interface/interface_shared.py", line 289, in _publish_pause
    self._publish(rec)
  File "/home/inside-tech/Desktop/image_segmentation/.venv/lib/python3.12/site-packages/wandb/sdk/interface/interface_sock.py", line 39, in _publish
    self._sock_client.send_record_publish(record)
  File "/home/inside-tech/Desktop/image_segmentation/.venv/lib/python3.12/site-packages/wandb/sdk/lib/sock_client.py", line 174, in send_record_publish
    self.send_server_request(server_req)
  File "/home/inside-tech/Desktop/image_segmentation/.venv/lib/python3.12/site-packages/wandb/sdk/lib/sock_client.py", line 154, in send_server_request
    self._send_message(msg)
  File "/home/inside-tech/Desktop/image_segmentation/.venv/lib/python3.12/site-packages/wandb/sdk/lib/sock_client.py", line 151, in _send_message
    self._sendall_with_error_handle(header + data)
  File "/home/inside-tech/Desktop/image_segmentation/.venv/lib/python3.12/site-packages/wandb/sdk/lib/sock_client.py", line 130, in _sendall_with_error_handle
    sent = self._sock.send(data)
           ^^^^^^^^^^^^^^^^^^^^^
BrokenPipeError: [Errno 32] Broken pipe

During handling of the above exception, another exception occurred:

Traceback (most recent call last):
  File "/home/inside-tech/Desktop/image_segmentation/.venv/lib/python3.12/site-packages/wandb/sdk/lib/redirect.py", line 659, in _on_write
    cb(written_data)
  File "/home/inside-tech/Desktop/image_segmentation/.venv/lib/python3.12/site-packages/wandb/sdk/wandb_run.py", line 2296, in <lambda>
    lambda data: self._console_raw_callback("stdout", data),
                 ^^^^^^^^^^^^^^^^^^^^^^^^^^^^^^^^^^^^^^^^^^
  File "/home/inside-tech/Desktop/image_segmentation/.venv/lib/python3.12/site-packages/wandb/sdk/wandb_run.py", line 401, in wrapper_fn
    return func(self, *args, **kwargs)
           ^^^^^^^^^^^^^^^^^^^^^^^^^^^
  File "/home/inside-tech/Desktop/image_segmentation/.venv/lib/python3.12/site-packages/wandb/sdk/wandb_run.py", line 1444, in _console_raw_callback
    self._backend.interface.publish_output_raw(name, data)
  File "/home/inside-tech/Desktop/image_segmentation/.venv/lib/python3.12/site-packages/wandb/sdk/interface/interface.py", line 761, in publish_output_raw
    self._publish_output_raw(o)
  File "/home/inside-tech/Desktop/image_segmentation/.venv/lib/python3.12/site-packages/wandb/sdk/interface/interface_shared.py", line 38, in _publish_output_raw
    self._publish(rec)
  File "/home/inside-tech/Desktop/image_segmentation/.venv/lib/python3.12/site-packages/wandb/sdk/interface/interface_sock.py", line 39, in _publish
    self._sock_client.send_record_publish(record)
  File "/home/inside-tech/Desktop/image_segmentation/.venv/lib/python3.12/site-packages/wandb/sdk/lib/sock_client.py", line 174, in send_record_publish
    self.send_server_request(server_req)
  File "/home/inside-tech/Desktop/image_segmentation/.venv/lib/python3.12/site-packages/wandb/sdk/lib/sock_client.py", line 154, in send_server_request
    self._send_message(msg)
  File "/home/inside-tech/Desktop/image_segmentation/.venv/lib/python3.12/site-packages/wandb/sdk/lib/sock_client.py", line 151, in _send_message
    self._sendall_with_error_handle(header + data)
  File "/home/inside-tech/Desktop/image_segmentation/.venv/lib/python3.12/site-packages/wandb/sdk/lib/sock_client.py", line 130, in _sendall_with_error_handle
    sent = self._sock.send(data)
           ^^^^^^^^^^^^^^^^^^^^^
BrokenPipeError: [Errno 32] Broken pipe
